Workbook

Sheet Evaluation of backbone models
A1: Moment magnitude (M) | B1: 6.5
A2: Joyner-Boore distance (RJB) | B2: 30
B3: 3-branch (original) | E3: 3-branch (reweighted) | H3: 5-branch (original) | M3: 5-branch (reweighted)
A4: Weight -> | B4: 0.185 | C4: 0.63 | D4: 0.185 | E4: 0.185 | F4: 0.63 | G4: 0.185 | H4: 0.101 | I4: 0.244 | J4: 0.309 | K4: 0.244 | L4: 0.101 | M4: 0.101 | N4: 0.244 | O4: 0.309 | P4: 0.244 | Q4: 0.101
A5: Period (s) | B5: Lower | C5: Central | D5: Upper | E5: Lower | F5: Central | G5: Upper | H5: 1st | I5: 2nd | J5: 3rd | K5: 4th | L5: 5th | M5: 1st | N5: 2nd | O5: 3rd | P5: 4th | Q5: 5th
A6: 0.01 | B6: {=EXP(INDIRECT("'3-branch model Rjb'!F"&S6)+INDIRECT("'3-branch model Rjb'!G"&S6)*'Evaluation of backbone models'!$B$1+INDIRECT("'3-branch model Rjb'!H"&S6)*(8.5-'Evaluation of backbone models'!$B$1)^2+INDIRECT("'3-branch model Rjb'!I"&S6)*LN(SQRT('Evaluation of backbone models'!$B$2^2+(INDIRECT("'3-branch model Rjb'!L"&S6)*EXP(INDIRECT("'3-branch model Rjb'!M"&S6)*'Evaluation of backbone models'!$B$1))^2))+(INDIRECT("'3-branch model Rjb'!J"&S6)+INDIRECT("'3-branch model Rjb'!K"&S6)*'Evaluation of backbone models'!$B$1)*'Evaluation of backbone models'!$B$2+IF('Evaluation of backbone models'!$B$2<=50,0,IF('Evaluation of backbone models'!$B$2>100,INDIRECT("'3-branch model Rjb'!N"&S6)*LN($B$2/50)+INDIRECT("'3-branch model Rjb'!O"&S6)*LN('Evaluation of backbone models'!$B$2/100),INDIRECT("'3-branch model Rjb'!N"&S6)*LN('Evaluation of backbone models'!$B$2/50))))} -> 0.42437738 | C6: {=EXP(INDIRECT("'3-branch model Rjb'!F"&T6)+INDIRECT("'3-branch model Rjb'!G"&T6)*'Evaluation of backbone models'!$B$1+INDIRECT("'3-branch model Rjb'!H"&T6)*(8.5-'Evaluation of backbone models'!$B$1)^2+INDIRECT("'3-branch model Rjb'!I"&T6)*LN(SQRT('Evaluation of backbone models'!$B$2^2+(INDIRECT("'3-branch model Rjb'!L"&T6)*EXP(INDIRECT("'3-branch model Rjb'!M"&T6)*'Evaluation of backbone models'!$B$1))^2))+(INDIRECT("'3-branch model Rjb'!J"&T6)+INDIRECT("'3-branch model Rjb'!K"&T6)*'Evaluation of backbone models'!$B$1)*'Evaluation of backbone models'!$B$2+IF('Evaluation of backbone models'!$B$2<=50,0,IF('Evaluation of backbone models'!$B$2>100,INDIRECT("'3-branch model Rjb'!N"&T6)*LN($B$2/50)+INDIRECT("'3-branch model Rjb'!O"&T6)*LN('Evaluation of backbone models'!$B$2/100),INDIRECT("'3-branch model Rjb'!N"&T6)*LN('Evaluation of backbone models'!$B$2/50))))} -> 1.243776 | D6: {=EXP(INDIRECT("'3-branch model Rjb'!F"&U6)+INDIRECT("'3-branch model Rjb'!G"&U6)*'Evaluation of backbone models'!$B$1+INDIRECT("'3-branch model Rjb'!H"&U6)*(8.5-'Evaluation of backbone models'!$B$1)^2+INDIRECT("'3-branch model Rjb'!I"&U6)*LN(SQRT('Evaluation of backbone models'!$B$2^2+(INDIRECT("'3-branch model Rjb'!L"&U6)*EXP(INDIRECT("'3-branch model Rjb'!M"&U6)*'Evaluation of backbone models'!$B$1))^2))+(INDIRECT("'3-branch model Rjb'!J"&U6)+INDIRECT("'3-branch model Rjb'!K"&U6)*'Evaluation of backbone models'!$B$1)*'Evaluation of backbone models'!$B$2+IF('Evaluation of backbone models'!$B$2<=50,0,IF('Evaluation of backbone models'!$B$2>100,INDIRECT("'3-branch model Rjb'!N"&U6)*LN($B$2/50)+INDIRECT("'3-branch model Rjb'!O"&U6)*LN('Evaluation of backbone models'!$B$2/100),INDIRECT("'3-branch model Rjb'!N"&U6)*LN('Evaluation of backbone models'!$B$2/50))))} -> 2.3946231 | E6: {=EXP(INDIRECT("'3-branch model Rjb'!F"&V6)+INDIRECT("'3-branch model Rjb'!G"&V6)*'Evaluation of backbone models'!$B$1+INDIRECT("'3-branch model Rjb'!H"&V6)*(8.5-'Evaluation of backbone models'!$B$1)^2+INDIRECT("'3-branch model Rjb'!I"&V6)*LN(SQRT('Evaluation of backbone models'!$B$2^2+(INDIRECT("'3-branch model Rjb'!L"&V6)*EXP(INDIRECT("'3-branch model Rjb'!M"&V6)*'Evaluation of backbone models'!$B$1))^2))+(INDIRECT("'3-branch model Rjb'!J"&V6)+INDIRECT("'3-branch model Rjb'!K"&V6)*'Evaluation of backbone models'!$B$1)*'Evaluation of backbone models'!$B$2+IF('Evaluation of backbone models'!$B$2<=50,0,IF('Evaluation of backbone models'!$B$2>100,INDIRECT("'3-branch model Rjb'!N"&V6)*LN($B$2/50)+INDIRECT("'3-branch model Rjb'!O"&V6)*LN('Evaluation of backbone models'!$B$2/100),INDIRECT("'3-branch model Rjb'!N"&V6)*LN('Evaluation of backbone models'!$B$2/50))))} -> 0.47329025 | F6: {=EXP(INDIRECT("'3-branch model Rjb'!F"&W6)+INDIRECT("'3-branch model Rjb'!G"&W6)*'Evaluation of backbone models'!$B$1+INDIRECT("'3-branch model Rjb'!H"&W6)*(8.5-'Evaluation of backbone models'!$B$1)^2+INDIRECT("'3-branch model Rjb'!I"&W6)*LN(SQRT('Evaluation of backbone models'!$B$2^2+(INDIRECT("'3-branch model Rjb'!L"&W6)*EXP(INDIRECT("'3-branch model Rjb'!M"&W6)*'Evaluation of backbone models'!$B$1))^2))+(INDIRECT("'3-branch model Rjb'!J"&W6)+INDIRECT("'3-branch model Rjb'!K"&W6)*'Evaluation of backbone models'!$B$1)*'Evaluation of backbone models'!$B$2+IF('Evaluation of backbone models'!$B$2<=50,0,IF('Evaluation of backbone models'!$B$2>100,INDIRECT("'3-branch model Rjb'!N"&W6)*LN($B$2/50)+INDIRECT("'3-branch model Rjb'!O"&W6)*LN('Evaluation of backbone models'!$B$2/100),INDIRECT("'3-branch model Rjb'!N"&W6)*LN('Evaluation of backbone models'!$B$2/50))))} -> 1.25656 | G6: {=EXP(INDIRECT("'3-branch model Rjb'!F"&X6)+INDIRECT("'3-branch model Rjb'!G"&X6)*'Evaluation of backbone models'!$B$1+INDIRECT("'3-branch model Rjb'!H"&X6)*(8.5-'Evaluation of backbone models'!$B$1)^2+INDIRECT("'3-branch model Rjb'!I"&X6)*LN(SQRT('Evaluation of backbone models'!$B$2^2+(INDIRECT("'3-branch model Rjb'!L"&X6)*EXP(INDIRECT("'3-branch model Rjb'!M"&X6)*'Evaluation of backbone models'!$B$1))^2))+(INDIRECT("'3-branch model Rjb'!J"&X6)+INDIRECT("'3-branch model Rjb'!K"&X6)*'Evaluation of backbone models'!$B$1)*'Evaluation of backbone models'!$B$2+IF('Evaluation of backbone models'!$B$2<=50,0,IF('Evaluation of backbone models'!$B$2>100,INDIRECT("'3-branch model Rjb'!N"&X6)*LN($B$2/50)+INDIRECT("'3-branch model Rjb'!O"&X6)*LN('Evaluation of backbone models'!$B$2/100),INDIRECT("'3-branch model Rjb'!N"&X6)*LN('Evaluation of backbone models'!$B$2/50))))} -> 2.4366893 | H6: {=EXP(INDIRECT("'5-branch model Rjb'!F"&Y6)+INDIRECT("'5-branch model Rjb'!G"&Y6)*'Evaluation of backbone models'!$B$1+INDIRECT("'5-branch model Rjb'!H"&Y6)*(8.5-'Evaluation of backbone models'!$B$1)^2+INDIRECT("'5-branch model Rjb'!I"&Y6)*LN(SQRT('Evaluation of backbone models'!$B$2^2+(INDIRECT("'5-branch model Rjb'!L"&Y6)*EXP(INDIRECT("'5-branch model Rjb'!M"&Y6)*'Evaluation of backbone models'!$B$1))^2))+(INDIRECT("'5-branch model Rjb'!J"&Y6)+INDIRECT("'5-branch model Rjb'!K"&Y6)*'Evaluation of backbone models'!$B$1)*'Evaluation of backbone models'!$B$2+IF('Evaluation of backbone models'!$B$2<=50,0,IF('Evaluation of backbone models'!$B$2>100,INDIRECT("'5-branch model Rjb'!N"&Y6)*LN($B$2/50)+INDIRECT("'5-branch model Rjb'!O"&Y6)*LN('Evaluation of backbone models'!$B$2/100),INDIRECT("'5-branch model Rjb'!N"&Y6)*LN('Evaluation of backbone models'!$B$2/50))))} -> 0.37184749 | I6: {=EXP(INDIRECT("'5-branch model Rjb'!F"&Z6)+INDIRECT("'5-branch model Rjb'!G"&Z6)*'Evaluation of backbone models'!$B$1+INDIRECT("'5-branch model Rjb'!H"&Z6)*(8.5-'Evaluation of backbone models'!$B$1)^2+INDIRECT("'5-branch model Rjb'!I"&Z6)*LN(SQRT('Evaluation of backbone models'!$B$2^2+(INDIRECT("'5-branch model Rjb'!L"&Z6)*EXP(INDIRECT("'5-branch model Rjb'!M"&Z6)*'Evaluation of backbone models'!$B$1))^2))+(INDIRECT("'5-branch model Rjb'!J"&Z6)+INDIRECT("'5-branch model Rjb'!K"&Z6)*'Evaluation of backbone models'!$B$1)*'Evaluation of backbone models'!$B$2+IF('Evaluation of backbone models'!$B$2<=50,0,IF('Evaluation of backbone models'!$B$2>100,INDIRECT("'5-branch model Rjb'!N"&Z6)*LN($B$2/50)+INDIRECT("'5-branch model Rjb'!O"&Z6)*LN('Evaluation of backbone models'!$B$2/100),INDIRECT("'5-branch model Rjb'!N"&Z6)*LN('Evaluation of backbone models'!$B$2/50))))} -> 0.89260199 | J6: {=EXP(INDIRECT("'5-branch model Rjb'!F"&AA6)+INDIRECT("'5-branch model Rjb'!G"&AA6)*'Evaluation of backbone models'!$B$1+INDIRECT("'5-branch model Rjb'!H"&AA6)*(8.5-'Evaluation of backbone models'!$B$1)^2+INDIRECT("'5-branch model Rjb'!I"&AA6)*LN(SQRT('Evaluation of backbone models'!$B$2^2+(INDIRECT("'5-branch model Rjb'!L"&AA6)*EXP(INDIRECT("'5-branch model Rjb'!M"&AA6)*'Evaluation of backbone models'!$B$1))^2))+(INDIRECT("'5-branch model Rjb'!J"&AA6)+INDIRECT("'5-branch model Rjb'!K"&AA6)*'Evaluation of backbone models'!$B$1)*'Evaluation of backbone models'!$B$2+IF('Evaluation of backbone models'!$B$2<=50,0,IF('Evaluation of backbone models'!$B$2>100,INDIRECT("'5-branch model Rjb'!N"&AA6)*LN($B$2/50)+INDIRECT("'5-branch model Rjb'!O"&AA6)*LN('Evaluation of backbone models'!$B$2/100),INDIRECT("'5-branch model Rjb'!N"&AA6)*LN('Evaluation of backbone models'!$B$2/50))))} -> 1.2436624 | K6: {=EXP(INDIRECT("'5-branch model Rjb'!F"&AB6)+INDIRECT("'5-branch model Rjb'!G"&AB6)*'Evaluation of backbone models'!$B$1+INDIRECT("'5-branch model Rjb'!H"&AB6)*(8.5-'Evaluation of backbone models'!$B$1)^2+INDIRECT("'5-branch model Rjb'!I"&AB6)*LN(SQRT('Evaluation of backbone models'!$B$2^2+(INDIRECT("'5-branch model Rjb'!L"&AB6)*EXP(INDIRECT("'5-branch model Rjb'!M"&AB6)*'Evaluation of backbone models'!$B$1))^2))+(INDIRECT("'5-branch model Rjb'!J"&AB6)+INDIRECT("'5-branch model Rjb'!K"&AB6)*'Evaluation of backbone models'!$B$1)*'Evaluation of backbone models'!$B$2+IF('Evaluation of backbone models'!$B$2<=50,0,IF('Evaluation of backbone models'!$B$2>100,INDIRECT("'5-branch model Rjb'!N"&AB6)*LN($B$2/50)+INDIRECT("'5-branch model Rjb'!O"&AB6)*LN('Evaluation of backbone models'!$B$2/100),INDIRECT("'5-branch model Rjb'!N"&AB6)*LN('Evaluation of backbone models'!$B$2/50))))} -> 1.7872043 | L6: {=EXP(INDIRECT("'5-branch model Rjb'!F"&AC6)+INDIRECT("'5-branch model Rjb'!G"&AC6)*'Evaluation of backbone models'!$B$1+INDIRECT("'5-branch model Rjb'!H"&AC6)*(8.5-'Evaluation of backbone models'!$B$1)^2+INDIRECT("'5-branch model Rjb'!I"&AC6)*LN(SQRT('Evaluation of backbone models'!$B$2^2+(INDIRECT("'5-branch model Rjb'!L"&AC6)*EXP(INDIRECT("'5-branch model Rjb'!M"&AC6)*'Evaluation of backbone models'!$B$1))^2))+(INDIRECT("'5-branch model Rjb'!J"&AC6)+INDIRECT("'5-branch model Rjb'!K"&AC6)*'Evaluation of backbone models'!$B$1)*'Evaluation of backbone models'!$B$2+IF('Evaluation of backbone models'!$B$2<=50,0,IF('Evaluation of backbone models'!$B$2>100,INDIRECT("'5-branch model Rjb'!N"&AC6)*LN($B$2/50)+INDIRECT("'5-branch model Rjb'!O"&AC6)*LN('Evaluation of backbone models'!$B$2/100),INDIRECT("'5-branch model Rjb'!N"&AC6)*LN('Evaluation of backbone models'!$B$2/50))))} -> 2.4607067 | M6: {=EXP(INDIRECT("'5-branch model Rjb'!F"&AD6)+INDIRECT("'5-branch model Rjb'!G"&AD6)*'Evaluation of backbone models'!$B$1+INDIRECT("'5-branch model Rjb'!H"&AD6)*(8.5-'Evaluation of backbone models'!$B$1)^2+INDIRECT("'5-branch model Rjb'!I"&AD6)*LN(SQRT('Evaluation of backbone models'!$B$2^2+(INDIRECT("'5-branch model Rjb'!L"&AD6)*EXP(INDIRECT("'5-branch model Rjb'!M"&AD6)*'Evaluation of backbone models'!$B$1))^2))+(INDIRECT("'5-branch model Rjb'!J"&AD6)+INDIRECT("'5-branch model Rjb'!K"&AD6)*'Evaluation of backbone models'!$B$1)*'Evaluation of backbone models'!$B$2+IF('Evaluation of backbone models'!$B$2<=50,0,IF('Evaluation of backbone models'!$B$2>100,INDIRECT("'5-branch model Rjb'!N"&AD6)*LN($B$2/50)+INDIRECT("'5-branch model Rjb'!O"&AD6)*LN('Evaluation of backbone models'!$B$2/100),INDIRECT("'5-branch model Rjb'!N"&AD6)*LN('Evaluation of backbone models'!$B$2/50))))} -> 0.46650115 | N6: {=EXP(INDIRECT("'5-branch model Rjb'!F"&AE6)+INDIRECT("'5-branch model Rjb'!G"&AE6)*'Evaluation of backbone models'!$B$1+INDIRECT("'5-branch model Rjb'!H"&AE6)*(8.5-'Evaluation of backbone models'!$B$1)^2+INDIRECT("'5-branch model Rjb'!I"&AE6)*LN(SQRT('Evaluation of backbone models'!$B$2^2+(INDIRECT("'5-branch model Rjb'!L"&AE6)*EXP(INDIRECT("'5-branch model Rjb'!M"&AE6)*'Evaluation of backbone models'!$B$1))^2))+(INDIRECT("'5-branch model Rjb'!J"&AE6)+INDIRECT("'5-branch model Rjb'!K"&AE6)*'Evaluation of backbone models'!$B$1)*'Evaluation of backbone models'!$B$2+IF('Evaluation of backbone models'!$B$2<=50,0,IF('Evaluation of backbone models'!$B$2>100,INDIRECT("'5-branch model Rjb'!N"&AE6)*LN($B$2/50)+INDIRECT("'5-branch model Rjb'!O"&AE6)*LN('Evaluation of backbone models'!$B$2/100),INDIRECT("'5-branch model Rjb'!N"&AE6)*LN('Evaluation of backbone models'!$B$2/50))))} -> 0.92348717 | O6: {=EXP(INDIRECT("'5-branch model Rjb'!F"&AF6)+INDIRECT("'5-branch model Rjb'!G"&AF6)*'Evaluation of backbone models'!$B$1+INDIRECT("'5-branch model Rjb'!H"&AF6)*(8.5-'Evaluation of backbone models'!$B$1)^2+INDIRECT("'5-branch model Rjb'!I"&AF6)*LN(SQRT('Evaluation of backbone models'!$B$2^2+(INDIRECT("'5-branch model Rjb'!L"&AF6)*EXP(INDIRECT("'5-branch model Rjb'!M"&AF6)*'Evaluation of backbone models'!$B$1))^2))+(INDIRECT("'5-branch model Rjb'!J"&AF6)+INDIRECT("'5-branch model Rjb'!K"&AF6)*'Evaluation of backbone models'!$B$1)*'Evaluation of backbone models'!$B$2+IF('Evaluation of backbone models'!$B$2<=50,0,IF('Evaluation of backbone models'!$B$2>100,INDIRECT("'5-branch model Rjb'!N"&AF6)*LN($B$2/50)+INDIRECT("'5-branch model Rjb'!O"&AF6)*LN('Evaluation of backbone models'!$B$2/100),INDIRECT("'5-branch model Rjb'!N"&AF6)*LN('Evaluation of backbone models'!$B$2/50))))} -> 1.2584764 | ... Q6: {=EXP(INDIRECT("'5-branch model Rjb'!F"&AH6)+INDIRECT("'5-branch model Rjb'!G"&AH6)*'Evaluation of backbone models'!$B$1+INDIRECT("'5-branch model Rjb'!H"&AH6)*(8.5-'Evaluation of backbone models'!$B$1)^2+INDIRECT("'5-branch model Rjb'!I"&AH6)*LN(SQRT('Evaluation of backbone models'!$B$2^2+(INDIRECT("'5-branch model Rjb'!L"&AH6)*EXP(INDIRECT("'5-branch model Rjb'!M"&AH6)*'Evaluation of backbone models'!$B$1))^2))+(INDIRECT("'5-branch model Rjb'!J"&AH6)+INDIRECT("'5-branch model Rjb'!K"&AH6)*'Evaluation of backbone models'!$B$1)*'Evaluation of backbone models'!$B$2+IF('Evaluation of backbone models'!$B$2<=50,0,IF('Evaluation of backbone models'!$B$2>100,INDIRECT("'5-branch model Rjb'!N"&AH6)*LN($B$2/50)+INDIRECT("'5-branch model Rjb'!O"&AH6)*LN('Evaluation of backbone models'!$B$2/100),INDIRECT("'5-branch model Rjb'!N"&AH6)*LN('Evaluation of backbone models'!$B$2/50))))} -> 2.8267027 | S6: 2 | T6: 3 | U6: 4 | V6: =S6+57 -> 59 | W6: =T6+57 -> 60 | X6: =U6+57 -> 61 | Y6: 2 | Z6: 3 | AA6: 4 | AB6: 5 | AC6: 6 | AD6: 97 | AE6: 98 | AF6: 99 | AG6: 100 | AH6: 101 | AI6: =('[1]Evaluation of backbone models'!B6-B6)/'[1]Evaluation of backbone models'!B6 -> -0.0012984116 | AJ6: =('[1]Evaluation of backbone models'!C6-C6)/'[1]Evaluation of backbone models'!C6 -> 0.012161842 | AK6: =('[1]Evaluation of backbone models'!D6-D6)/'[1]Evaluation of backbone models'!D6 -> 0.1429954 | AL6: =('[1]Evaluation of backbone models'!E6-E6)/'[1]Evaluation of backbone models'!E6 -> 0.0052690415 | AM6: =('[1]Evaluation of backbone models'!F6-F6)/'[1]Evaluation of backbone models'!F6 -> 0.0010996561 | AN6: =('[1]Evaluation of backbone models'!G6-G6)/'[1]Evaluation of backbone models'!G6 -> 0.0045357801
A7: 0.025 | B7: {=EXP(INDIRECT("'3-branch model Rjb'!F"&S7)+INDIRECT("'3-branch model Rjb'!G"&S7)*'Evaluation of backbone models'!$B$1+INDIRECT("'3-branch model Rjb'!H"&S7)*(8.5-'Evaluation of backbone models'!$B$1)^2+INDIRECT("'3-branch model Rjb'!I"&S7)*LN(SQRT('Evaluation of backbone models'!$B$2^2+(INDIRECT("'3-branch model Rjb'!L"&S7)*EXP(INDIRECT("'3-branch model Rjb'!M"&S7)*'Evaluation of backbone models'!$B$1))^2))+(INDIRECT("'3-branch model Rjb'!J"&S7)+INDIRECT("'3-branch model Rjb'!K"&S7)*'Evaluation of backbone models'!$B$1)*'Evaluation of backbone models'!$B$2+IF('Evaluation of backbone models'!$B$2<=50,0,IF('Evaluation of backbone models'!$B$2>100,INDIRECT("'3-branch model Rjb'!N"&S7)*LN($B$2/50)+INDIRECT("'3-branch model Rjb'!O"&S7)*LN('Evaluation of backbone models'!$B$2/100),INDIRECT("'3-branch model Rjb'!N"&S7)*LN('Evaluation of backbone models'!$B$2/50))))} -> 0.49592256 | C7: {=EXP(INDIRECT("'3-branch model Rjb'!F"&T7)+INDIRECT("'3-branch model Rjb'!G"&T7)*'Evaluation of backbone models'!$B$1+INDIRECT("'3-branch model Rjb'!H"&T7)*(8.5-'Evaluation of backbone models'!$B$1)^2+INDIRECT("'3-branch model Rjb'!I"&T7)*LN(SQRT('Evaluation of backbone models'!$B$2^2+(INDIRECT("'3-branch model Rjb'!L"&T7)*EXP(INDIRECT("'3-branch model Rjb'!M"&T7)*'Evaluation of backbone models'!$B$1))^2))+(INDIRECT("'3-branch model Rjb'!J"&T7)+INDIRECT("'3-branch model Rjb'!K"&T7)*'Evaluation of backbone models'!$B$1)*'Evaluation of backbone models'!$B$2+IF('Evaluation of backbone models'!$B$2<=50,0,IF('Evaluation of backbone models'!$B$2>100,INDIRECT("'3-branch model Rjb'!N"&T7)*LN($B$2/50)+INDIRECT("'3-branch model Rjb'!O"&T7)*LN('Evaluation of backbone models'!$B$2/100),INDIRECT("'3-branch model Rjb'!N"&T7)*LN('Evaluation of backbone models'!$B$2/50))))} -> 1.4802597 | D7: {=EXP(INDIRECT("'3-branch model Rjb'!F"&U7)+INDIRECT("'3-branch model Rjb'!G"&U7)*'Evaluation of backbone models'!$B$1+INDIRECT("'3-branch model Rjb'!H"&U7)*(8.5-'Evaluation of backbone models'!$B$1)^2+INDIRECT("'3-branch model Rjb'!I"&U7)*LN(SQRT('Evaluation of backbone models'!$B$2^2+(INDIRECT("'3-branch model Rjb'!L"&U7)*EXP(INDIRECT("'3-branch model Rjb'!M"&U7)*'Evaluation of backbone models'!$B$1))^2))+(INDIRECT("'3-branch model Rjb'!J"&U7)+INDIRECT("'3-branch model Rjb'!K"&U7)*'Evaluation of backbone models'!$B$1)*'Evaluation of backbone models'!$B$2+IF('Evaluation of backbone models'!$B$2<=50,0,IF('Evaluation of backbone models'!$B$2>100,INDIRECT("'3-branch model Rjb'!N"&U7)*LN($B$2/50)+INDIRECT("'3-branch model Rjb'!O"&U7)*LN('Evaluation of backbone models'!$B$2/100),INDIRECT("'3-branch model Rjb'!N"&U7)*LN('Evaluation of backbone models'!$B$2/50))))} -> 3.9362002 | E7: {=EXP(INDIRECT("'3-branch model Rjb'!F"&V7)+INDIRECT("'3-branch model Rjb'!G"&V7)*'Evaluation of backbone models'!$B$1+INDIRECT("'3-branch model Rjb'!H"&V7)*(8.5-'Evaluation of backbone models'!$B$1)^2+INDIRECT("'3-branch model Rjb'!I"&V7)*LN(SQRT('Evaluation of backbone models'!$B$2^2+(INDIRECT("'3-branch model Rjb'!L"&V7)*EXP(INDIRECT("'3-branch model Rjb'!M"&V7)*'Evaluation of backbone models'!$B$1))^2))+(INDIRECT("'3-branch model Rjb'!J"&V7)+INDIRECT("'3-branch model Rjb'!K"&V7)*'Evaluation of backbone models'!$B$1)*'Evaluation of backbone models'!$B$2+IF('Evaluation of backbone models'!$B$2<=50,0,IF('Evaluation of backbone models'!$B$2>100,INDIRECT("'3-branch model Rjb'!N"&V7)*LN($B$2/50)+INDIRECT("'3-branch model Rjb'!O"&V7)*LN('Evaluation of backbone models'!$B$2/100),INDIRECT("'3-branch model Rjb'!N"&V7)*LN('Evaluation of backbone models'!$B$2/50))))} -> 0.56299092 | F7: {=EXP(INDIRECT("'3-branch model Rjb'!F"&W7)+INDIRECT("'3-branch model Rjb'!G"&W7)*'Evaluation of backbone models'!$B$1+INDIRECT("'3-branch model Rjb'!H"&W7)*(8.5-'Evaluation of backbone models'!$B$1)^2+INDIRECT("'3-branch model Rjb'!I"&W7)*LN(SQRT('Evaluation of backbone models'!$B$2^2+(INDIRECT("'3-branch model Rjb'!L"&W7)*EXP(INDIRECT("'3-branch model Rjb'!M"&W7)*'Evaluation of backbone models'!$B$1))^2))+(INDIRECT("'3-branch model Rjb'!J"&W7)+INDIRECT("'3-branch model Rjb'!K"&W7)*'Evaluation of backbone models'!$B$1)*'Evaluation of backbone models'!$B$2+IF('Evaluation of backbone models'!$B$2<=50,0,IF('Evaluation of backbone models'!$B$2>100,INDIRECT("'3-branch model Rjb'!N"&W7)*LN($B$2/50)+INDIRECT("'3-branch model Rjb'!O"&W7)*LN('Evaluation of backbone models'!$B$2/100),INDIRECT("'3-branch model Rjb'!N"&W7)*LN('Evaluation of backbone models'!$B$2/50))))} -> 1.4901492 | G7: {=EXP(INDIRECT("'3-branch model Rjb'!F"&X7)+INDIRECT("'3-branch model Rjb'!G"&X7)*'Evaluation of backbone models'!$B$1+INDIRECT("'3-branch model Rjb'!H"&X7)*(8.5-'Evaluation of backbone models'!$B$1)^2+INDIRECT("'3-branch model Rjb'!I"&X7)*LN(SQRT('Evaluation of backbone models'!$B$2^2+(INDIRECT("'3-branch model Rjb'!L"&X7)*EXP(INDIRECT("'3-branch model Rjb'!M"&X7)*'Evaluation of backbone models'!$B$1))^2))+(INDIRECT("'3-branch model Rjb'!J"&X7)+INDIRECT("'3-branch model Rjb'!K"&X7)*'Evaluation of backbone models'!$B$1)*'Evaluation of backbone models'!$B$2+IF('Evaluation of backbone models'!$B$2<=50,0,IF('Evaluation of backbone models'!$B$2>100,INDIRECT("'3-branch model Rjb'!N"&X7)*LN($B$2/50)+INDIRECT("'3-branch model Rjb'!O"&X7)*LN('Evaluation of backbone models'!$B$2/100),INDIRECT("'3-branch model Rjb'!N"&X7)*LN('Evaluation of backbone models'!$B$2/50))))} -> 4.0388061 | H7: {=EXP(INDIRECT("'5-branch model Rjb'!F"&Y7)+INDIRECT("'5-branch model Rjb'!G"&Y7)*'Evaluation of backbone models'!$B$1+INDIRECT("'5-branch model Rjb'!H"&Y7)*(8.5-'Evaluation of backbone models'!$B$1)^2+INDIRECT("'5-branch model Rjb'!I"&Y7)*LN(SQRT('Evaluation of backbone models'!$B$2^2+(INDIRECT("'5-branch model Rjb'!L"&Y7)*EXP(INDIRECT("'5-branch model Rjb'!M"&Y7)*'Evaluation of backbone models'!$B$1))^2))+(INDIRECT("'5-branch model Rjb'!J"&Y7)+INDIRECT("'5-branch model Rjb'!K"&Y7)*'Evaluation of backbone models'!$B$1)*'Evaluation of backbone models'!$B$2+IF('Evaluation of backbone models'!$B$2<=50,0,IF('Evaluation of backbone models'!$B$2>100,INDIRECT("'5-branch model Rjb'!N"&Y7)*LN($B$2/50)+INDIRECT("'5-branch model Rjb'!O"&Y7)*LN('Evaluation of backbone models'!$B$2/100),INDIRECT("'5-branch model Rjb'!N"&Y7)*LN('Evaluation of backbone models'!$B$2/50))))} -> 0.40328003 | I7: {=EXP(INDIRECT("'5-branch model Rjb'!F"&Z7)+INDIRECT("'5-branch model Rjb'!G"&Z7)*'Evaluation of backbone models'!$B$1+INDIRECT("'5-branch model Rjb'!H"&Z7)*(8.5-'Evaluation of backbone models'!$B$1)^2+INDIRECT("'5-branch model Rjb'!I"&Z7)*LN(SQRT('Evaluation of backbone models'!$B$2^2+(INDIRECT("'5-branch model Rjb'!L"&Z7)*EXP(INDIRECT("'5-branch model Rjb'!M"&Z7)*'Evaluation of backbone models'!$B$1))^2))+(INDIRECT("'5-branch model Rjb'!J"&Z7)+INDIRECT("'5-branch model Rjb'!K"&Z7)*'Evaluation of backbone models'!$B$1)*'Evaluation of backbone models'!$B$2+IF('Evaluation of backbone models'!$B$2<=50,0,IF('Evaluation of backbone models'!$B$2>100,INDIRECT("'5-branch model Rjb'!N"&Z7)*LN($B$2/50)+INDIRECT("'5-branch model Rjb'!O"&Z7)*LN('Evaluation of backbone models'!$B$2/100),INDIRECT("'5-branch model Rjb'!N"&Z7)*LN('Evaluation of backbone models'!$B$2/50))))} -> 0.94606044 | J7: {=EXP(INDIRECT("'5-branch model Rjb'!F"&AA7)+INDIRECT("'5-branch model Rjb'!G"&AA7)*'Evaluation of backbone models'!$B$1+INDIRECT("'5-branch model Rjb'!H"&AA7)*(8.5-'Evaluation of backbone models'!$B$1)^2+INDIRECT("'5-branch model Rjb'!I"&AA7)*LN(SQRT('Evaluation of backbone models'!$B$2^2+(INDIRECT("'5-branch model Rjb'!L"&AA7)*EXP(INDIRECT("'5-branch model Rjb'!M"&AA7)*'Evaluation of backbone models'!$B$1))^2))+(INDIRECT("'5-branch model Rjb'!J"&AA7)+INDIRECT("'5-branch model Rjb'!K"&AA7)*'Evaluation of backbone models'!$B$1)*'Evaluation of backbone models'!$B$2+IF('Evaluation of backbone models'!$B$2<=50,0,IF('Evaluation of backbone models'!$B$2>100,INDIRECT("'5-branch model Rjb'!N"&AA7)*LN($B$2/50)+INDIRECT("'5-branch model Rjb'!O"&AA7)*LN('Evaluation of backbone models'!$B$2/100),INDIRECT("'5-branch model Rjb'!N"&AA7)*LN('Evaluation of backbone models'!$B$2/50))))} -> 1.4796313 | K7: {=EXP(INDIRECT("'5-branch model Rjb'!F"&AB7)+INDIRECT("'5-branch model Rjb'!G"&AB7)*'Evaluation of backbone models'!$B$1+INDIRECT("'5-branch model Rjb'!H"&AB7)*(8.5-'Evaluation of backbone models'!$B$1)^2+INDIRECT("'5-branch model Rjb'!I"&AB7)*LN(SQRT('Evaluation of backbone models'!$B$2^2+(INDIRECT("'5-branch model Rjb'!L"&AB7)*EXP(INDIRECT("'5-branch model Rjb'!M"&AB7)*'Evaluation of backbone models'!$B$1))^2))+(INDIRECT("'5-branch model Rjb'!J"&AB7)+INDIRECT("'5-branch model Rjb'!K"&AB7)*'Evaluation of backbone models'!$B$1)*'Evaluation of backbone models'!$B$2+IF('Evaluation of backbone models'!$B$2<=50,0,IF('Evaluation of backbone models'!$B$2>100,INDIRECT("'5-branch model Rjb'!N"&AB7)*LN($B$2/50)+INDIRECT("'5-branch model Rjb'!O"&AB7)*LN('Evaluation of backbone models'!$B$2/100),INDIRECT("'5-branch model Rjb'!N"&AB7)*LN('Evaluation of backbone models'!$B$2/50))))} -> 2.1129701 | L7: {=EXP(INDIRECT("'5-branch model Rjb'!F"&AC7)+INDIRECT("'5-branch model Rjb'!G"&AC7)*'Evaluation of backbone models'!$B$1+INDIRECT("'5-branch model Rjb'!H"&AC7)*(8.5-'Evaluation of backbone models'!$B$1)^2+INDIRECT("'5-branch model Rjb'!I"&AC7)*LN(SQRT('Evaluation of backbone models'!$B$2^2+(INDIRECT("'5-branch model Rjb'!L"&AC7)*EXP(INDIRECT("'5-branch model Rjb'!M"&AC7)*'Evaluation of backbone models'!$B$1))^2))+(INDIRECT("'5-branch model Rjb'!J"&AC7)+INDIRECT("'5-branch model Rjb'!K"&AC7)*'Evaluation of backbone models'!$B$1)*'Evaluation of backbone models'!$B$2+IF('Evaluation of backbone models'!$B$2<=50,0,IF('Evaluation of backbone models'!$B$2>100,INDIRECT("'5-branch model Rjb'!N"&AC7)*LN($B$2/50)+INDIRECT("'5-branch model Rjb'!O"&AC7)*LN('Evaluation of backbone models'!$B$2/100),INDIRECT("'5-branch model Rjb'!N"&AC7)*LN('Evaluation of backbone models'!$B$2/50))))} -> 4.0807867 | M7: {=EXP(INDIRECT("'5-branch model Rjb'!F"&AD7)+INDIRECT("'5-branch model Rjb'!G"&AD7)*'Evaluation of backbone models'!$B$1+INDIRECT("'5-branch model Rjb'!H"&AD7)*(8.5-'Evaluation of backbone models'!$B$1)^2+INDIRECT("'5-branch model Rjb'!I"&AD7)*LN(SQRT('Evaluation of backbone models'!$B$2^2+(INDIRECT("'5-branch model Rjb'!L"&AD7)*EXP(INDIRECT("'5-branch model Rjb'!M"&AD7)*'Evaluation of backbone models'!$B$1))^2))+(INDIRECT("'5-branch model Rjb'!J"&AD7)+INDIRECT("'5-branch model Rjb'!K"&AD7)*'Evaluation of backbone models'!$B$1)*'Evaluation of backbone models'!$B$2+IF('Evaluation of backbone models'!$B$2<=50,0,IF('Evaluation of backbone models'!$B$2>100,INDIRECT("'5-branch model Rjb'!N"&AD7)*LN($B$2/50)+INDIRECT("'5-branch model Rjb'!O"&AD7)*LN('Evaluation of backbone models'!$B$2/100),INDIRECT("'5-branch model Rjb'!N"&AD7)*LN('Evaluation of backbone models'!$B$2/50))))} -> 0.55607331 | N7: {=EXP(INDIRECT("'5-branch model Rjb'!F"&AE7)+INDIRECT("'5-branch model Rjb'!G"&AE7)*'Evaluation of backbone models'!$B$1+INDIRECT("'5-branch model Rjb'!H"&AE7)*(8.5-'Evaluation of backbone models'!$B$1)^2+INDIRECT("'5-branch model Rjb'!I"&AE7)*LN(SQRT('Evaluation of backbone models'!$B$2^2+(INDIRECT("'5-branch model Rjb'!L"&AE7)*EXP(INDIRECT("'5-branch model Rjb'!M"&AE7)*'Evaluation of backbone models'!$B$1))^2))+(INDIRECT("'5-branch model Rjb'!J"&AE7)+INDIRECT("'5-branch model Rjb'!K"&AE7)*'Evaluation of backbone models'!$B$1)*'Evaluation of backbone models'!$B$2+IF('Evaluation of backbone models'!$B$2<=50,0,IF('Evaluation of backbone models'!$B$2>100,INDIRECT("'5-branch model Rjb'!N"&AE7)*LN($B$2/50)+INDIRECT("'5-branch model Rjb'!O"&AE7)*LN('Evaluation of backbone models'!$B$2/100),INDIRECT("'5-branch model Rjb'!N"&AE7)*LN('Evaluation of backbone models'!$B$2/50))))} -> 0.97310701 | O7: {=EXP(INDIRECT("'5-branch model Rjb'!F"&AF7)+INDIRECT("'5-branch model Rjb'!G"&AF7)*'Evaluation of backbone models'!$B$1+INDIRECT("'5-branch model Rjb'!H"&AF7)*(8.5-'Evaluation of backbone models'!$B$1)^2+INDIRECT("'5-branch model Rjb'!I"&AF7)*LN(SQRT('Evaluation of backbone models'!$B$2^2+(INDIRECT("'5-branch model Rjb'!L"&AF7)*EXP(INDIRECT("'5-branch model Rjb'!M"&AF7)*'Evaluation of backbone models'!$B$1))^2))+(INDIRECT("'5-branch model Rjb'!J"&AF7)+INDIRECT("'5-branch model Rjb'!K"&AF7)*'Evaluation of backbone models'!$B$1)*'Evaluation of backbone models'!$B$2+IF('Evaluation of backbone models'!$B$2<=50,0,IF('Evaluation of backbone models'!$B$2>100,INDIRECT("'5-branch model Rjb'!N"&AF7)*LN($B$2/50)+INDIRECT("'5-branch model Rjb'!O"&AF7)*LN('Evaluation of backbone models'!$B$2/100),INDIRECT("'5-branch model Rjb'!N"&AF7)*LN('Evaluation of backbone models'!$B$2/50))))} -> 1.489834 | ... Q7: {=EXP(INDIRECT("'5-branch model Rjb'!F"&AH7)+INDIRECT("'5-branch model Rjb'!G"&AH7)*'Evaluation of backbone models'!$B$1+INDIRECT("'5-branch model Rjb'!H"&AH7)*(8.5-'Evaluation of backbone models'!$B$1)^2+INDIRECT("'5-branch model Rjb'!I"&AH7)*LN(SQRT('Evaluation of backbone models'!$B$2^2+(INDIRECT("'5-branch model Rjb'!L"&AH7)*EXP(INDIRECT("'5-branch model Rjb'!M"&AH7)*'Evaluation of backbone models'!$B$1))^2))+(INDIRECT("'5-branch model Rjb'!J"&AH7)+INDIRECT("'5-branch model Rjb'!K"&AH7)*'Evaluation of backbone models'!$B$1)*'Evaluation of backbone models'!$B$2+IF('Evaluation of backbone models'!$B$2<=50,0,IF('Evaluation of backbone models'!$B$2>100,INDIRECT("'5-branch model Rjb'!N"&AH7)*LN($B$2/50)+INDIRECT("'5-branch model Rjb'!O"&AH7)*LN('Evaluation of backbone models'!$B$2/100),INDIRECT("'5-branch model Rjb'!N"&AH7)*LN('Evaluation of backbone models'!$B$2/50))))} -> 4.4380951 | S7: 5 | T7: 6 | U7: 7 | V7: =S7+57 -> 62 | W7: =T7+57 -> 63 | X7: =U7+57 -> 64 | Y7: 7 | Z7: 8 | AA7: 9 | AB7: 10 | AC7: 11 | AD7: 102 | AE7: 103 | AF7: 104 | AG7: 105 | AH7: 106 | AI7: =('[1]Evaluation of backbone models'!B7-B7)/'[1]Evaluation of backbone models'!B7 -> -0.0020239799 | AJ7: =('[1]Evaluation of backbone models'!C7-C7)/'[1]Evaluation of backbone models'!C7 -> 0.0038118046 | AK7: =('[1]Evaluation of backbone models'!D7-D7)/'[1]Evaluation of backbone models'!D7 -> 0.1193411 | AL7: =('[1]Evaluation of backbone models'!E7-E7)/'[1]Evaluation of backbone models'!E7 -> 0.0056451522 | AM7: =('[1]Evaluation of backbone models'!F7-F7)/'[1]Evaluation of backbone models'!F7 -> -0.00018928813 | AN7: =('[1]Evaluation of backbone models'!G7-G7)/'[1]Evaluation of backbone models'!G7 -> 0.004624955
A8: 0.05 | B8: {=EXP(INDIRECT("'3-branch model Rjb'!F"&S8)+INDIRECT("'3-branch model Rjb'!G"&S8)*'Evaluation of backbone models'!$B$1+INDIRECT("'3-branch model Rjb'!H"&S8)*(8.5-'Evaluation of backbone models'!$B$1)^2+INDIRECT("'3-branch model Rjb'!I"&S8)*LN(SQRT('Evaluation of backbone models'!$B$2^2+(INDIRECT("'3-branch model Rjb'!L"&S8)*EXP(INDIRECT("'3-branch model Rjb'!M"&S8)*'Evaluation of backbone models'!$B$1))^2))+(INDIRECT("'3-branch model Rjb'!J"&S8)+INDIRECT("'3-branch model Rjb'!K"&S8)*'Evaluation of backbone models'!$B$1)*'Evaluation of backbone models'!$B$2+IF('Evaluation of backbone models'!$B$2<=50,0,IF('Evaluation of backbone models'!$B$2>100,INDIRECT("'3-branch model Rjb'!N"&S8)*LN($B$2/50)+INDIRECT("'3-branch model Rjb'!O"&S8)*LN('Evaluation of backbone models'!$B$2/100),INDIRECT("'3-branch model Rjb'!N"&S8)*LN('Evaluation of backbone models'!$B$2/50))))} -> 0.69029129 | C8: {=EXP(INDIRECT("'3-branch model Rjb'!F"&T8)+INDIRECT("'3-branch model Rjb'!G"&T8)*'Evaluation of backbone models'!$B$1+INDIRECT("'3-branch model Rjb'!H"&T8)*(8.5-'Evaluation of backbone models'!$B$1)^2+INDIRECT("'3-branch model Rjb'!I"&T8)*LN(SQRT('Evaluation of backbone models'!$B$2^2+(INDIRECT("'3-branch model Rjb'!L"&T8)*EXP(INDIRECT("'3-branch model Rjb'!M"&T8)*'Evaluation of backbone models'!$B$1))^2))+(INDIRECT("'3-branch model Rjb'!J"&T8)+INDIRECT("'3-branch model Rjb'!K"&T8)*'Evaluation of backbone models'!$B$1)*'Evaluation of backbone models'!$B$2+IF('Evaluation of backbone models'!$B$2<=50,0,IF('Evaluation of backbone models'!$B$2>100,INDIRECT("'3-branch model Rjb'!N"&T8)*LN($B$2/50)+INDIRECT("'3-branch model Rjb'!O"&T8)*LN('Evaluation of backbone models'!$B$2/100),INDIRECT("'3-branch model Rjb'!N"&T8)*LN('Evaluation of backbone models'!$B$2/50))))} -> 2.0899245 | D8: {=EXP(INDIRECT("'3-branch model Rjb'!F"&U8)+INDIRECT("'3-branch model Rjb'!G"&U8)*'Evaluation of backbone models'!$B$1+INDIRECT("'3-branch model Rjb'!H"&U8)*(8.5-'Evaluation of backbone models'!$B$1)^2+INDIRECT("'3-branch model Rjb'!I"&U8)*LN(SQRT('Evaluation of backbone models'!$B$2^2+(INDIRECT("'3-branch model Rjb'!L"&U8)*EXP(INDIRECT("'3-branch model Rjb'!M"&U8)*'Evaluation of backbone models'!$B$1))^2))+(INDIRECT("'3-branch model Rjb'!J"&U8)+INDIRECT("'3-branch model Rjb'!K"&U8)*'Evaluation of backbone models'!$B$1)*'Evaluation of backbone models'!$B$2+IF('Evaluation of backbone models'!$B$2<=50,0,IF('Evaluation of backbone models'!$B$2>100,INDIRECT("'3-branch model Rjb'!N"&U8)*LN($B$2/50)+INDIRECT("'3-branch model Rjb'!O"&U8)*LN('Evaluation of backbone models'!$B$2/100),INDIRECT("'3-branch model Rjb'!N"&U8)*LN('Evaluation of backbone models'!$B$2/50))))} -> 4.4658743 | E8: {=EXP(INDIRECT("'3-branch model Rjb'!F"&V8)+INDIRECT("'3-branch model Rjb'!G"&V8)*'Evaluation of backbone models'!$B$1+INDIRECT("'3-branch model Rjb'!H"&V8)*(8.5-'Evaluation of backbone models'!$B$1)^2+INDIRECT("'3-branch model Rjb'!I"&V8)*LN(SQRT('Evaluation of backbone models'!$B$2^2+(INDIRECT("'3-branch model Rjb'!L"&V8)*EXP(INDIRECT("'3-branch model Rjb'!M"&V8)*'Evaluation of backbone models'!$B$1))^2))+(INDIRECT("'3-branch model Rjb'!J"&V8)+INDIRECT("'3-branch model Rjb'!K"&V8)*'Evaluation of backbone models'!$B$1)*'Evaluation of backbone models'!$B$2+IF('Evaluation of backbone models'!$B$2<=50,0,IF('Evaluation of backbone models'!$B$2>100,INDIRECT("'3-branch model Rjb'!N"&V8)*LN($B$2/50)+INDIRECT("'3-branch model Rjb'!O"&V8)*LN('Evaluation of backbone models'!$B$2/100),INDIRECT("'3-branch model Rjb'!N"&V8)*LN('Evaluation of backbone models'!$B$2/50))))} -> 0.80411014 | F8: {=EXP(INDIRECT("'3-branch model Rjb'!F"&W8)+INDIRECT("'3-branch model Rjb'!G"&W8)*'Evaluation of backbone models'!$B$1+INDIRECT("'3-branch model Rjb'!H"&W8)*(8.5-'Evaluation of backbone models'!$B$1)^2+INDIRECT("'3-branch model Rjb'!I"&W8)*LN(SQRT('Evaluation of backbone models'!$B$2^2+(INDIRECT("'3-branch model Rjb'!L"&W8)*EXP(INDIRECT("'3-branch model Rjb'!M"&W8)*'Evaluation of backbone models'!$B$1))^2))+(INDIRECT("'3-branch model Rjb'!J"&W8)+INDIRECT("'3-branch model Rjb'!K"&W8)*'Evaluation of backbone models'!$B$1)*'Evaluation of backbone models'!$B$2+IF('Evaluation of backbone models'!$B$2<=50,0,IF('Evaluation of backbone models'!$B$2>100,INDIRECT("'3-branch model Rjb'!N"&W8)*LN($B$2/50)+INDIRECT("'3-branch model Rjb'!O"&W8)*LN('Evaluation of backbone models'!$B$2/100),INDIRECT("'3-branch model Rjb'!N"&W8)*LN('Evaluation of backbone models'!$B$2/50))))} -> 2.0913395 | G8: {=EXP(INDIRECT("'3-branch model Rjb'!F"&X8)+INDIRECT("'3-branch model Rjb'!G"&X8)*'Evaluation of backbone models'!$B$1+INDIRECT("'3-branch model Rjb'!H"&X8)*(8.5-'Evaluation of backbone models'!$B$1)^2+INDIRECT("'3-branch model Rjb'!I"&X8)*LN(SQRT('Evaluation of backbone models'!$B$2^2+(INDIRECT("'3-branch model Rjb'!L"&X8)*EXP(INDIRECT("'3-branch model Rjb'!M"&X8)*'Evaluation of backbone models'!$B$1))^2))+(INDIRECT("'3-branch model Rjb'!J"&X8)+INDIRECT("'3-branch model Rjb'!K"&X8)*'Evaluation of backbone models'!$B$1)*'Evaluation of backbone models'!$B$2+IF('Evaluation of backbone models'!$B$2<=50,0,IF('Evaluation of backbone models'!$B$2>100,INDIRECT("'3-branch model Rjb'!N"&X8)*LN($B$2/50)+INDIRECT("'3-branch model Rjb'!O"&X8)*LN('Evaluation of backbone models'!$B$2/100),INDIRECT("'3-branch model Rjb'!N"&X8)*LN('Evaluation of backbone models'!$B$2/50))))} -> 4.5306622 | H8: {=EXP(INDIRECT("'5-branch model Rjb'!F"&Y8)+INDIRECT("'5-branch model Rjb'!G"&Y8)*'Evaluation of backbone models'!$B$1+INDIRECT("'5-branch model Rjb'!H"&Y8)*(8.5-'Evaluation of backbone models'!$B$1)^2+INDIRECT("'5-branch model Rjb'!I"&Y8)*LN(SQRT('Evaluation of backbone models'!$B$2^2+(INDIRECT("'5-branch model Rjb'!L"&Y8)*EXP(INDIRECT("'5-branch model Rjb'!M"&Y8)*'Evaluation of backbone models'!$B$1))^2))+(INDIRECT("'5-branch model Rjb'!J"&Y8)+INDIRECT("'5-branch model Rjb'!K"&Y8)*'Evaluation of backbone models'!$B$1)*'Evaluation of backbone models'!$B$2+IF('Evaluation of backbone models'!$B$2<=50,0,IF('Evaluation of backbone models'!$B$2>100,INDIRECT("'5-branch model Rjb'!N"&Y8)*LN($B$2/50)+INDIRECT("'5-branch model Rjb'!O"&Y8)*LN('Evaluation of backbone models'!$B$2/100),INDIRECT("'5-branch model Rjb'!N"&Y8)*LN('Evaluation of backbone models'!$B$2/50))))} -> 0.52088061 | I8: {=EXP(INDIRECT("'5-branch model Rjb'!F"&Z8)+INDIRECT("'5-branch model Rjb'!G"&Z8)*'Evaluation of backbone models'!$B$1+INDIRECT("'5-branch model Rjb'!H"&Z8)*(8.5-'Evaluation of backbone models'!$B$1)^2+INDIRECT("'5-branch model Rjb'!I"&Z8)*LN(SQRT('Evaluation of backbone models'!$B$2^2+(INDIRECT("'5-branch model Rjb'!L"&Z8)*EXP(INDIRECT("'5-branch model Rjb'!M"&Z8)*'Evaluation of backbone models'!$B$1))^2))+(INDIRECT("'5-branch model Rjb'!J"&Z8)+INDIRECT("'5-branch model Rjb'!K"&Z8)*'Evaluation of backbone models'!$B$1)*'Evaluation of backbone models'!$B$2+IF('Evaluation of backbone models'!$B$2<=50,0,IF('Evaluation of backbone models'!$B$2>100,INDIRECT("'5-branch model Rjb'!N"&Z8)*LN($B$2/50)+INDIRECT("'5-branch model Rjb'!O"&Z8)*LN('Evaluation of backbone models'!$B$2/100),INDIRECT("'5-branch model Rjb'!N"&Z8)*LN('Evaluation of backbone models'!$B$2/50))))} -> 1.1655697 | J8: {=EXP(INDIRECT("'5-branch model Rjb'!F"&AA8)+INDIRECT("'5-branch model Rjb'!G"&AA8)*'Evaluation of backbone models'!$B$1+INDIRECT("'5-branch model Rjb'!H"&AA8)*(8.5-'Evaluation of backbone models'!$B$1)^2+INDIRECT("'5-branch model Rjb'!I"&AA8)*LN(SQRT('Evaluation of backbone models'!$B$2^2+(INDIRECT("'5-branch model Rjb'!L"&AA8)*EXP(INDIRECT("'5-branch model Rjb'!M"&AA8)*'Evaluation of backbone models'!$B$1))^2))+(INDIRECT("'5-branch model Rjb'!J"&AA8)+INDIRECT("'5-branch model Rjb'!K"&AA8)*'Evaluation of backbone models'!$B$1)*'Evaluation of backbone models'!$B$2+IF('Evaluation of backbone models'!$B$2<=50,0,IF('Evaluation of backbone models'!$B$2>100,INDIRECT("'5-branch model Rjb'!N"&AA8)*LN($B$2/50)+INDIRECT("'5-branch model Rjb'!O"&AA8)*LN('Evaluation of backbone models'!$B$2/100),INDIRECT("'5-branch model Rjb'!N"&AA8)*LN('Evaluation of backbone models'!$B$2/50))))} -> 2.0963309 | K8: {=EXP(INDIRECT("'5-branch model Rjb'!F"&AB8)+INDIRECT("'5-branch model Rjb'!G"&AB8)*'Evaluation of backbone models'!$B$1+INDIRECT("'5-branch model Rjb'!H"&AB8)*(8.5-'Evaluation of backbone models'!$B$1)^2+INDIRECT("'5-branch model Rjb'!I"&AB8)*LN(SQRT('Evaluation of backbone models'!$B$2^2+(INDIRECT("'5-branch model Rjb'!L"&AB8)*EXP(INDIRECT("'5-branch model Rjb'!M"&AB8)*'Evaluation of backbone models'!$B$1))^2))+(INDIRECT("'5-branch model Rjb'!J"&AB8)+INDIRECT("'5-branch model Rjb'!K"&AB8)*'Evaluation of backbone models'!$B$1)*'Evaluation of backbone models'!$B$2+IF('Evaluation of backbone models'!$B$2<=50,0,IF('Evaluation of backbone models'!$B$2>100,INDIRECT("'5-branch model Rjb'!N"&AB8)*LN($B$2/50)+INDIRECT("'5-branch model Rjb'!O"&AB8)*LN('Evaluation of backbone models'!$B$2/100),INDIRECT("'5-branch model Rjb'!N"&AB8)*LN('Evaluation of backbone models'!$B$2/50))))} -> 3.0146362 | L8: {=EXP(INDIRECT("'5-branch model Rjb'!F"&AC8)+INDIRECT("'5-branch model Rjb'!G"&AC8)*'Evaluation of backbone models'!$B$1+INDIRECT("'5-branch model Rjb'!H"&AC8)*(8.5-'Evaluation of backbone models'!$B$1)^2+INDIRECT("'5-branch model Rjb'!I"&AC8)*LN(SQRT('Evaluation of backbone models'!$B$2^2+(INDIRECT("'5-branch model Rjb'!L"&AC8)*EXP(INDIRECT("'5-branch model Rjb'!M"&AC8)*'Evaluation of backbone models'!$B$1))^2))+(INDIRECT("'5-branch model Rjb'!J"&AC8)+INDIRECT("'5-branch model Rjb'!K"&AC8)*'Evaluation of backbone models'!$B$1)*'Evaluation of backbone models'!$B$2+IF('Evaluation of backbone models'!$B$2<=50,0,IF('Evaluation of backbone models'!$B$2>100,INDIRECT("'5-branch model Rjb'!N"&AC8)*LN($B$2/50)+INDIRECT("'5-branch model Rjb'!O"&AC8)*LN('Evaluation of backbone models'!$B$2/100),INDIRECT("'5-branch model Rjb'!N"&AC8)*LN('Evaluation of backbone models'!$B$2/50))))} -> 4.5823653 | M8: {=EXP(INDIRECT("'5-branch model Rjb'!F"&AD8)+INDIRECT("'5-branch model Rjb'!G"&AD8)*'Evaluation of backbone models'!$B$1+INDIRECT("'5-branch model Rjb'!H"&AD8)*(8.5-'Evaluation of backbone models'!$B$1)^2+INDIRECT("'5-branch model Rjb'!I"&AD8)*LN(SQRT('Evaluation of backbone models'!$B$2^2+(INDIRECT("'5-branch model Rjb'!L"&AD8)*EXP(INDIRECT("'5-branch model Rjb'!M"&AD8)*'Evaluation of backbone models'!$B$1))^2))+(INDIRECT("'5-branch model Rjb'!J"&AD8)+INDIRECT("'5-branch model Rjb'!K"&AD8)*'Evaluation of backbone models'!$B$1)*'Evaluation of backbone models'!$B$2+IF('Evaluation of backbone models'!$B$2<=50,0,IF('Evaluation of backbone models'!$B$2>100,INDIRECT("'5-branch model Rjb'!N"&AD8)*LN($B$2/50)+INDIRECT("'5-branch model Rjb'!O"&AD8)*LN('Evaluation of backbone models'!$B$2/100),INDIRECT("'5-branch model Rjb'!N"&AD8)*LN('Evaluation of backbone models'!$B$2/50))))} -> 0.79411299 | N8: {=EXP(INDIRECT("'5-branch model Rjb'!F"&AE8)+INDIRECT("'5-branch model Rjb'!G"&AE8)*'Evaluation of backbone models'!$B$1+INDIRECT("'5-branch model Rjb'!H"&AE8)*(8.5-'Evaluation of backbone models'!$B$1)^2+INDIRECT("'5-branch model Rjb'!I"&AE8)*LN(SQRT('Evaluation of backbone models'!$B$2^2+(INDIRECT("'5-branch model Rjb'!L"&AE8)*EXP(INDIRECT("'5-branch model Rjb'!M"&AE8)*'Evaluation of backbone models'!$B$1))^2))+(INDIRECT("'5-branch model Rjb'!J"&AE8)+INDIRECT("'5-branch model Rjb'!K"&AE8)*'Evaluation of backbone models'!$B$1)*'Evaluation of backbone models'!$B$2+IF('Evaluation of backbone models'!$B$2<=50,0,IF('Evaluation of backbone models'!$B$2>100,INDIRECT("'5-branch model Rjb'!N"&AE8)*LN($B$2/50)+INDIRECT("'5-branch model Rjb'!O"&AE8)*LN('Evaluation of backbone models'!$B$2/100),INDIRECT("'5-branch model Rjb'!N"&AE8)*LN('Evaluation of backbone models'!$B$2/50))))} -> 1.2070993 | O8: {=EXP(INDIRECT("'5-branch model Rjb'!F"&AF8)+INDIRECT("'5-branch model Rjb'!G"&AF8)*'Evaluation of backbone models'!$B$1+INDIRECT("'5-branch model Rjb'!H"&AF8)*(8.5-'Evaluation of backbone models'!$B$1)^2+INDIRECT("'5-branch model Rjb'!I"&AF8)*LN(SQRT('Evaluation of backbone models'!$B$2^2+(INDIRECT("'5-branch model Rjb'!L"&AF8)*EXP(INDIRECT("'5-branch model Rjb'!M"&AF8)*'Evaluation of backbone models'!$B$1))^2))+(INDIRECT("'5-branch model Rjb'!J"&AF8)+INDIRECT("'5-branch model Rjb'!K"&AF8)*'Evaluation of backbone models'!$B$1)*'Evaluation of backbone models'!$B$2+IF('Evaluation of backbone models'!$B$2<=50,0,IF('Evaluation of backbone models'!$B$2>100,INDIRECT("'5-branch model Rjb'!N"&AF8)*LN($B$2/50)+INDIRECT("'5-branch model Rjb'!O"&AF8)*LN('Evaluation of backbone models'!$B$2/100),INDIRECT("'5-branch model Rjb'!N"&AF8)*LN('Evaluation of backbone models'!$B$2/50))))} -> 2.0928456 | ... Q8: {=EXP(INDIRECT("'5-branch model Rjb'!F"&AH8)+INDIRECT("'5-branch model Rjb'!G"&AH8)*'Evaluation of backbone models'!$B$1+INDIRECT("'5-branch model Rjb'!H"&AH8)*(8.5-'Evaluation of backbone models'!$B$1)^2+INDIRECT("'5-branch model Rjb'!I"&AH8)*LN(SQRT('Evaluation of backbone models'!$B$2^2+(INDIRECT("'5-branch model Rjb'!L"&AH8)*EXP(INDIRECT("'5-branch model Rjb'!M"&AH8)*'Evaluation of backbone models'!$B$1))^2))+(INDIRECT("'5-branch model Rjb'!J"&AH8)+INDIRECT("'5-branch model Rjb'!K"&AH8)*'Evaluation of backbone models'!$B$1)*'Evaluation of backbone models'!$B$2+IF('Evaluation of backbone models'!$B$2<=50,0,IF('Evaluation of backbone models'!$B$2>100,INDIRECT("'5-branch model Rjb'!N"&AH8)*LN($B$2/50)+INDIRECT("'5-branch model Rjb'!O"&AH8)*LN('Evaluation of backbone models'!$B$2/100),INDIRECT("'5-branch model Rjb'!N"&AH8)*LN('Evaluation of backbone models'!$B$2/50))))} -> 5.3209959 | S8: 8 | T8: 9 | U8: 10 | V8: =S8+57 -> 65 | W8: =T8+57 -> 66 | X8: =U8+57 -> 67 | Y8: 12 | Z8: 13 | AA8: 14 | AB8: 15 | AC8: 16 | AD8: 107 | AE8: 108 | AF8: 109 | AG8: 110 | AH8: 111 | AI8: =('[1]Evaluation of backbone models'!B8-B8)/'[1]Evaluation of backbone models'!B8 -> -0.0038144649 | AJ8: =('[1]Evaluation of backbone models'!C8-C8)/'[1]Evaluation of backbone models'!C8 -> 0.008547004 | AK8: =('[1]Evaluation of backbone models'!D8-D8)/'[1]Evaluation of backbone models'!D8 -> 0.1525931 | AL8: =('[1]Evaluation of backbone models'!E8-E8)/'[1]Evaluation of backbone models'!E8 -> 0.0032848558 | AM8: =('[1]Evaluation of backbone models'!F8-F8)/'[1]Evaluation of backbone models'!F8 -> 0.00079613938 | AN8: =('[1]Evaluation of backbone models'!G8-G8)/'[1]Evaluation of backbone models'!G8 -> 0.0018384475
A9: 0.075 | B9: {=EXP(INDIRECT("'3-branch model Rjb'!F"&S9)+INDIRECT("'3-branch model Rjb'!G"&S9)*'Evaluation of backbone models'!$B$1+INDIRECT("'3-branch model Rjb'!H"&S9)*(8.5-'Evaluation of backbone models'!$B$1)^2+INDIRECT("'3-branch model Rjb'!I"&S9)*LN(SQRT('Evaluation of backbone models'!$B$2^2+(INDIRECT("'3-branch model Rjb'!L"&S9)*EXP(INDIRECT("'3-branch model Rjb'!M"&S9)*'Evaluation of backbone models'!$B$1))^2))+(INDIRECT("'3-branch model Rjb'!J"&S9)+INDIRECT("'3-branch model Rjb'!K"&S9)*'Evaluation of backbone models'!$B$1)*'Evaluation of backbone models'!$B$2+IF('Evaluation of backbone models'!$B$2<=50,0,IF('Evaluation of backbone models'!$B$2>100,INDIRECT("'3-branch model Rjb'!N"&S9)*LN($B$2/50)+INDIRECT("'3-branch model Rjb'!O"&S9)*LN('Evaluation of backbone models'!$B$2/100),INDIRECT("'3-branch model Rjb'!N"&S9)*LN('Evaluation of backbone models'!$B$2/50))))} -> 0.80861063 | C9: {=EXP(INDIRECT("'3-branch model Rjb'!F"&T9)+INDIRECT("'3-branch model Rjb'!G"&T9)*'Evaluation of backbone models'!$B$1+INDIRECT("'3-branch model Rjb'!H"&T9)*(8.5-'Evaluation of backbone models'!$B$1)^2+INDIRECT("'3-branch model Rjb'!I"&T9)*LN(SQRT('Evaluation of backbone models'!$B$2^2+(INDIRECT("'3-branch model Rjb'!L"&T9)*EXP(INDIRECT("'3-branch model Rjb'!M"&T9)*'Evaluation of backbone models'!$B$1))^2))+(INDIRECT("'3-branch model Rjb'!J"&T9)+INDIRECT("'3-branch model Rjb'!K"&T9)*'Evaluation of backbone models'!$B$1)*'Evaluation of backbone models'!$B$2+IF('Evaluation of backbone models'!$B$2<=50,0,IF('Evaluation of backbone models'!$B$2>100,INDIRECT("'3-branch model Rjb'!N"&T9)*LN($B$2/50)+INDIRECT("'3-branch model Rjb'!O"&T9)*LN('Evaluation of backbone models'!$B$2/100),INDIRECT("'3-branch model Rjb'!N"&T9)*LN('Evaluation of backbone models'!$B$2/50))))} -> 2.4239254 | D9: {=EXP(INDIRECT("'3-branch model Rjb'!F"&U9)+INDIRECT("'3-branch model Rjb'!G"&U9)*'Evaluation of backbone models'!$B$1+INDIRECT("'3-branch model Rjb'!H"&U9)*(8.5-'Evaluation of backbone models'!$B$1)^2+INDIRECT("'3-branch model Rjb'!I"&U9)*LN(SQRT('Evaluation of backbone models'!$B$2^2+(INDIRECT("'3-branch model Rjb'!L"&U9)*EXP(INDIRECT("'3-branch model Rjb'!M"&U9)*'Evaluation of backbone models'!$B$1))^2))+(INDIRECT("'3-branch model Rjb'!J"&U9)+INDIRECT("'3-branch model Rjb'!K"&U9)*'Evaluation of backbone models'!$B$1)*'Evaluation of backbone models'!$B$2+IF('Evaluation of backbone models'!$B$2<=50,0,IF('Evaluation of backbone models'!$B$2>100,INDIRECT("'3-branch model Rjb'!N"&U9)*LN($B$2/50)+INDIRECT("'3-branch model Rjb'!O"&U9)*LN('Evaluation of backbone models'!$B$2/100),INDIRECT("'3-branch model Rjb'!N"&U9)*LN('Evaluation of backbone models'!$B$2/50))))} -> 4.3118759 | E9: {=EXP(INDIRECT("'3-branch model Rjb'!F"&V9)+INDIRECT("'3-branch model Rjb'!G"&V9)*'Evaluation of backbone models'!$B$1+INDIRECT("'3-branch model Rjb'!H"&V9)*(8.5-'Evaluation of backbone models'!$B$1)^2+INDIRECT("'3-branch model Rjb'!I"&V9)*LN(SQRT('Evaluation of backbone models'!$B$2^2+(INDIRECT("'3-branch model Rjb'!L"&V9)*EXP(INDIRECT("'3-branch model Rjb'!M"&V9)*'Evaluation of backbone models'!$B$1))^2))+(INDIRECT("'3-branch model Rjb'!J"&V9)+INDIRECT("'3-branch model Rjb'!K"&V9)*'Evaluation of backbone models'!$B$1)*'Evaluation of backbone models'!$B$2+IF('Evaluation of backbone models'!$B$2<=50,0,IF('Evaluation of backbone models'!$B$2>100,INDIRECT("'3-branch model Rjb'!N"&V9)*LN($B$2/50)+INDIRECT("'3-branch model Rjb'!O"&V9)*LN('Evaluation of backbone models'!$B$2/100),INDIRECT("'3-branch model Rjb'!N"&V9)*LN('Evaluation of backbone models'!$B$2/50))))} -> 0.91871252 | F9: {=EXP(INDIRECT("'3-branch model Rjb'!F"&W9)+INDIRECT("'3-branch model Rjb'!G"&W9)*'Evaluation of backbone models'!$B$1+INDIRECT("'3-branch model Rjb'!H"&W9)*(8.5-'Evaluation of backbone models'!$B$1)^2+INDIRECT("'3-branch model Rjb'!I"&W9)*LN(SQRT('Evaluation of backbone models'!$B$2^2+(INDIRECT("'3-branch model Rjb'!L"&W9)*EXP(INDIRECT("'3-branch model Rjb'!M"&W9)*'Evaluation of backbone models'!$B$1))^2))+(INDIRECT("'3-branch model Rjb'!J"&W9)+INDIRECT("'3-branch model Rjb'!K"&W9)*'Evaluation of backbone models'!$B$1)*'Evaluation of backbone models'!$B$2+IF('Evaluation of backbone models'!$B$2<=50,0,IF('Evaluation of backbone models'!$B$2>100,INDIRECT("'3-branch model Rjb'!N"&W9)*LN($B$2/50)+INDIRECT("'3-branch model Rjb'!O"&W9)*LN('Evaluation of backbone models'!$B$2/100),INDIRECT("'3-branch model Rjb'!N"&W9)*LN('Evaluation of backbone models'!$B$2/50))))} -> 2.4349319 | G9: {=EXP(INDIRECT("'3-branch model Rjb'!F"&X9)+INDIRECT("'3-branch model Rjb'!G"&X9)*'Evaluation of backbone models'!$B$1+INDIRECT("'3-branch model Rjb'!H"&X9)*(8.5-'Evaluation of backbone models'!$B$1)^2+INDIRECT("'3-branch model Rjb'!I"&X9)*LN(SQRT('Evaluation of backbone models'!$B$2^2+(INDIRECT("'3-branch model Rjb'!L"&X9)*EXP(INDIRECT("'3-branch model Rjb'!M"&X9)*'Evaluation of backbone models'!$B$1))^2))+(INDIRECT("'3-branch model Rjb'!J"&X9)+INDIRECT("'3-branch model Rjb'!K"&X9)*'Evaluation of backbone models'!$B$1)*'Evaluation of backbone models'!$B$2+IF('Evaluation of backbone models'!$B$2<=50,0,IF('Evaluation of backbone models'!$B$2>100,INDIRECT("'3-branch model Rjb'!N"&X9)*LN($B$2/50)+INDIRECT("'3-branch model Rjb'!O"&X9)*LN('Evaluation of backbone models'!$B$2/100),INDIRECT("'3-branch model Rjb'!N"&X9)*LN('Evaluation of backbone models'!$B$2/50))))} -> 4.3752466 | H9: {=EXP(INDIRECT("'5-branch model Rjb'!F"&Y9)+INDIRECT("'5-branch model Rjb'!G"&Y9)*'Evaluation of backbone models'!$B$1+INDIRECT("'5-branch model Rjb'!H"&Y9)*(8.5-'Evaluation of backbone models'!$B$1)^2+INDIRECT("'5-branch model Rjb'!I"&Y9)*LN(SQRT('Evaluation of backbone models'!$B$2^2+(INDIRECT("'5-branch model Rjb'!L"&Y9)*EXP(INDIRECT("'5-branch model Rjb'!M"&Y9)*'Evaluation of backbone models'!$B$1))^2))+(INDIRECT("'5-branch model Rjb'!J"&Y9)+INDIRECT("'5-branch model Rjb'!K"&Y9)*'Evaluation of backbone models'!$B$1)*'Evaluation of backbone models'!$B$2+IF('Evaluation of backbone models'!$B$2<=50,0,IF('Evaluation of backbone models'!$B$2>100,INDIRECT("'5-branch model Rjb'!N"&Y9)*LN($B$2/50)+INDIRECT("'5-branch model Rjb'!O"&Y9)*LN('Evaluation of backbone models'!$B$2/100),INDIRECT("'5-branch model Rjb'!N"&Y9)*LN('Evaluation of backbone models'!$B$2/50))))} -> 0.64412005 | I9: {=EXP(INDIRECT("'5-branch model Rjb'!F"&Z9)+INDIRECT("'5-branch model Rjb'!G"&Z9)*'Evaluation of backbone models'!$B$1+INDIRECT("'5-branch model Rjb'!H"&Z9)*(8.5-'Evaluation of backbone models'!$B$1)^2+INDIRECT("'5-branch model Rjb'!I"&Z9)*LN(SQRT('Evaluation of backbone models'!$B$2^2+(INDIRECT("'5-branch model Rjb'!L"&Z9)*EXP(INDIRECT("'5-branch model Rjb'!M"&Z9)*'Evaluation of backbone models'!$B$1))^2))+(INDIRECT("'5-branch model Rjb'!J"&Z9)+INDIRECT("'5-branch model Rjb'!K"&Z9)*'Evaluation of backbone models'!$B$1)*'Evaluation of backbone models'!$B$2+IF('Evaluation of backbone models'!$B$2<=50,0,IF('Evaluation of backbone models'!$B$2>100,INDIRECT("'5-branch model Rjb'!N"&Z9)*LN($B$2/50)+INDIRECT("'5-branch model Rjb'!O"&Z9)*LN('Evaluation of backbone models'!$B$2/100),INDIRECT("'5-branch model Rjb'!N"&Z9)*LN('Evaluation of backbone models'!$B$2/50))))} -> 1.4652735 | J9: {=EXP(INDIRECT("'5-branch model Rjb'!F"&AA9)+INDIRECT("'5-branch model Rjb'!G"&AA9)*'Evaluation of backbone models'!$B$1+INDIRECT("'5-branch model Rjb'!H"&AA9)*(8.5-'Evaluation of backbone models'!$B$1)^2+INDIRECT("'5-branch model Rjb'!I"&AA9)*LN(SQRT('Evaluation of backbone models'!$B$2^2+(INDIRECT("'5-branch model Rjb'!L"&AA9)*EXP(INDIRECT("'5-branch model Rjb'!M"&AA9)*'Evaluation of backbone models'!$B$1))^2))+(INDIRECT("'5-branch model Rjb'!J"&AA9)+INDIRECT("'5-branch model Rjb'!K"&AA9)*'Evaluation of backbone models'!$B$1)*'Evaluation of backbone models'!$B$2+IF('Evaluation of backbone models'!$B$2<=50,0,IF('Evaluation of backbone models'!$B$2>100,INDIRECT("'5-branch model Rjb'!N"&AA9)*LN($B$2/50)+INDIRECT("'5-branch model Rjb'!O"&AA9)*LN('Evaluation of backbone models'!$B$2/100),INDIRECT("'5-branch model Rjb'!N"&AA9)*LN('Evaluation of backbone models'!$B$2/50))))} -> 2.4268897 | K9: {=EXP(INDIRECT("'5-branch model Rjb'!F"&AB9)+INDIRECT("'5-branch model Rjb'!G"&AB9)*'Evaluation of backbone models'!$B$1+INDIRECT("'5-branch model Rjb'!H"&AB9)*(8.5-'Evaluation of backbone models'!$B$1)^2+INDIRECT("'5-branch model Rjb'!I"&AB9)*LN(SQRT('Evaluation of backbone models'!$B$2^2+(INDIRECT("'5-branch model Rjb'!L"&AB9)*EXP(INDIRECT("'5-branch model Rjb'!M"&AB9)*'Evaluation of backbone models'!$B$1))^2))+(INDIRECT("'5-branch model Rjb'!J"&AB9)+INDIRECT("'5-branch model Rjb'!K"&AB9)*'Evaluation of backbone models'!$B$1)*'Evaluation of backbone models'!$B$2+IF('Evaluation of backbone models'!$B$2<=50,0,IF('Evaluation of backbone models'!$B$2>100,INDIRECT("'5-branch model Rjb'!N"&AB9)*LN($B$2/50)+INDIRECT("'5-branch model Rjb'!O"&AB9)*LN('Evaluation of backbone models'!$B$2/100),INDIRECT("'5-branch model Rjb'!N"&AB9)*LN('Evaluation of backbone models'!$B$2/50))))} -> 3.5096458 | L9: {=EXP(INDIRECT("'5-branch model Rjb'!F"&AC9)+INDIRECT("'5-branch model Rjb'!G"&AC9)*'Evaluation of backbone models'!$B$1+INDIRECT("'5-branch model Rjb'!H"&AC9)*(8.5-'Evaluation of backbone models'!$B$1)^2+INDIRECT("'5-branch model Rjb'!I"&AC9)*LN(SQRT('Evaluation of backbone models'!$B$2^2+(INDIRECT("'5-branch model Rjb'!L"&AC9)*EXP(INDIRECT("'5-branch model Rjb'!M"&AC9)*'Evaluation of backbone models'!$B$1))^2))+(INDIRECT("'5-branch model Rjb'!J"&AC9)+INDIRECT("'5-branch model Rjb'!K"&AC9)*'Evaluation of backbone models'!$B$1)*'Evaluation of backbone models'!$B$2+IF('Evaluation of backbone models'!$B$2<=50,0,IF('Evaluation of backbone models'!$B$2>100,INDIRECT("'5-branch model Rjb'!N"&AC9)*LN($B$2/50)+INDIRECT("'5-branch model Rjb'!O"&AC9)*LN('Evaluation of backbone models'!$B$2/100),INDIRECT("'5-branch model Rjb'!N"&AC9)*LN('Evaluation of backbone models'!$B$2/50))))} -> 4.424386 | M9: {=EXP(INDIRECT("'5-branch model Rjb'!F"&AD9)+INDIRECT("'5-branch model Rjb'!G"&AD9)*'Evaluation of backbone models'!$B$1+INDIRECT("'5-branch model Rjb'!H"&AD9)*(8.5-'Evaluation of backbone models'!$B$1)^2+INDIRECT("'5-branch model Rjb'!I"&AD9)*LN(SQRT('Evaluation of backbone models'!$B$2^2+(INDIRECT("'5-branch model Rjb'!L"&AD9)*EXP(INDIRECT("'5-branch model Rjb'!M"&AD9)*'Evaluation of backbone models'!$B$1))^2))+(INDIRECT("'5-branch model Rjb'!J"&AD9)+INDIRECT("'5-branch model Rjb'!K"&AD9)*'Evaluation of backbone models'!$B$1)*'Evaluation of backbone models'!$B$2+IF('Evaluation of backbone models'!$B$2<=50,0,IF('Evaluation of backbone models'!$B$2>100,INDIRECT("'5-branch model Rjb'!N"&AD9)*LN($B$2/50)+INDIRECT("'5-branch model Rjb'!O"&AD9)*LN('Evaluation of backbone models'!$B$2/100),INDIRECT("'5-branch model Rjb'!N"&AD9)*LN('Evaluation of backbone models'!$B$2/50))))} -> 0.90427162 | N9: {=EXP(INDIRECT("'5-branch model Rjb'!F"&AE9)+INDIRECT("'5-branch model Rjb'!G"&AE9)*'Evaluation of backbone models'!$B$1+INDIRECT("'5-branch model Rjb'!H"&AE9)*(8.5-'Evaluation of backbone models'!$B$1)^2+INDIRECT("'5-branch model Rjb'!I"&AE9)*LN(SQRT('Evaluation of backbone models'!$B$2^2+(INDIRECT("'5-branch model Rjb'!L"&AE9)*EXP(INDIRECT("'5-branch model Rjb'!M"&AE9)*'Evaluation of backbone models'!$B$1))^2))+(INDIRECT("'5-branch model Rjb'!J"&AE9)+INDIRECT("'5-branch model Rjb'!K"&AE9)*'Evaluation of backbone models'!$B$1)*'Evaluation of backbone models'!$B$2+IF('Evaluation of backbone models'!$B$2<=50,0,IF('Evaluation of backbone models'!$B$2>100,INDIRECT("'5-branch model Rjb'!N"&AE9)*LN($B$2/50)+INDIRECT("'5-branch model Rjb'!O"&AE9)*LN('Evaluation of backbone models'!$B$2/100),INDIRECT("'5-branch model Rjb'!N"&AE9)*LN('Evaluation of backbone models'!$B$2/50))))} -> 1.5145148 | O9: {=EXP(INDIRECT("'5-branch model Rjb'!F"&AF9)+INDIRECT("'5-branch model Rjb'!G"&AF9)*'Evaluation of backbone models'!$B$1+INDIRECT("'5-branch model Rjb'!H"&AF9)*(8.5-'Evaluation of backbone models'!$B$1)^2+INDIRECT("'5-branch model Rjb'!I"&AF9)*LN(SQRT('Evaluation of backbone models'!$B$2^2+(INDIRECT("'5-branch model Rjb'!L"&AF9)*EXP(INDIRECT("'5-branch model Rjb'!M"&AF9)*'Evaluation of backbone models'!$B$1))^2))+(INDIRECT("'5-branch model Rjb'!J"&AF9)+INDIRECT("'5-branch model Rjb'!K"&AF9)*'Evaluation of backbone models'!$B$1)*'Evaluation of backbone models'!$B$2+IF('Evaluation of backbone models'!$B$2<=50,0,IF('Evaluation of backbone models'!$B$2>100,INDIRECT("'5-branch model Rjb'!N"&AF9)*LN($B$2/50)+INDIRECT("'5-branch model Rjb'!O"&AF9)*LN('Evaluation of backbone models'!$B$2/100),INDIRECT("'5-branch model Rjb'!N"&AF9)*LN('Evaluation of backbone models'!$B$2/50))))} -> 2.4366038 | ... Q9: {=EXP(INDIRECT("'5-branch model Rjb'!F"&AH9)+INDIRECT("'5-branch model Rjb'!G"&AH9)*'Evaluation of backbone models'!$B$1+INDIRECT("'5-branch model Rjb'!H"&AH9)*(8.5-'Evaluation of backbone models'!$B$1)^2+INDIRECT("'5-branch model Rjb'!I"&AH9)*LN(SQRT('Evaluation of backbone models'!$B$2^2+(INDIRECT("'5-branch model Rjb'!L"&AH9)*EXP(INDIRECT("'5-branch model Rjb'!M"&AH9)*'Evaluation of backbone models'!$B$1))^2))+(INDIRECT("'5-branch model Rjb'!J"&AH9)+INDIRECT("'5-branch model Rjb'!K"&AH9)*'Evaluation of backbone models'!$B$1)*'Evaluation of backbone models'!$B$2+IF('Evaluation of backbone models'!$B$2<=50,0,IF('Evaluation of backbone models'!$B$2>100,INDIRECT("'5-branch model Rjb'!N"&AH9)*LN($B$2/50)+INDIRECT("'5-branch model Rjb'!O"&AH9)*LN('Evaluation of backbone models'!$B$2/100),INDIRECT("'5-branch model Rjb'!N"&AH9)*LN('Evaluation of backbone models'!$B$2/50))))} -> 5.3856284 | S9: 11 | T9: 12 | U9: 13 | V9: =S9+57 -> 68 | W9: =T9+57 -> 69 | X9: =U9+57 -> 70 | Y9: 17 | Z9: 18 | AA9: 19 | AB9: 20 | AC9: 21 | AD9: 112 | AE9: 113 | AF9: 114 | AG9: 115 | AH9: 116 | AI9: =('[1]Evaluation of backbone models'!B9-B9)/'[1]Evaluation of backbone models'!B9 -> -0.0057009059 | AJ9: =('[1]Evaluation of backbone models'!C9-C9)/'[1]Evaluation of backbone models'!C9 -> 0.0037043636 | AK9: =('[1]Evaluation of backbone models'!D9-D9)/'[1]Evaluation of backbone models'!D9 -> 0.18409056 | AL9: =('[1]Evaluation of backbone models'!E9-E9)/'[1]Evaluation of backbone models'!E9 -> 0.0039539411 | AM9: =('[1]Evaluation of backbone models'!F9-F9)/'[1]Evaluation of backbone models'!F9 -> 0.0014880909 | AN9: =('[1]Evaluation of backbone models'!G9-G9)/'[1]Evaluation of backbone models'!G9 -> 0.0062023233
